2021-03-14T16:45:47 HOSTNAME APP_NAME: Watching for file changes with StatReloader
2021-03-14T16:46:30 HOSTNAME APP_NAME: /home/hernangonzales/projects/test/unico/unico/urls.py changed, reloading.
2021-03-14T16:46:32 HOSTNAME APP_NAME: Watching for file changes with StatReloader
2021-03-14T16:46:59 HOSTNAME APP_NAME: Watching for file changes with StatReloader
2021-03-14T16:47:54 HOSTNAME APP_NAME: Watching for file changes with StatReloader
2021-03-14T17:07:20 HOSTNAME APP_NAME: Watching for file changes with StatReloader
2021-03-14T17:07:47 HOSTNAME APP_NAME: "GET /markets?district=BRAS HTTP/1.1" 301 0
2021-03-14T17:07:47 HOSTNAME APP_NAME: "GET /markets/?district=BRAS HTTP/1.1" 200 2002
2021-03-14T17:08:04 HOSTNAME APP_NAME: Internal Server Error: /markets/
Traceback (most recent call last):
  File "/home/hernangonzales/projects/test/unico/env/lib/python3.8/site-packages/django/db/backends/utils.py", line 84, in _execute
    return self.cursor.execute(sql, params)
psycopg2.errors.UniqueViolation: duplicate key value violates unique constraint "markets_market_pkey"
DETAIL:  Key (id)=(1) already exists.


The above exception was the direct cause of the following exception:

Traceback (most recent call last):
  File "/home/hernangonzales/projects/test/unico/env/lib/python3.8/site-packages/django/core/handlers/exception.py", line 47, in inner
    response = get_response(request)
  File "/home/hernangonzales/projects/test/unico/env/lib/python3.8/site-packages/django/core/handlers/base.py", line 181, in _get_response
    response = wrapped_callback(request, *callback_args, **callback_kwargs)
  File "/home/hernangonzales/projects/test/unico/env/lib/python3.8/site-packages/django/views/decorators/csrf.py", line 54, in wrapped_view
    return view_func(*args, **kwargs)
  File "/home/hernangonzales/projects/test/unico/env/lib/python3.8/site-packages/django/views/generic/base.py", line 70, in view
    return self.dispatch(request, *args, **kwargs)
  File "/home/hernangonzales/projects/test/unico/env/lib/python3.8/site-packages/rest_framework/views.py", line 509, in dispatch
    response = self.handle_exception(exc)
  File "/home/hernangonzales/projects/test/unico/env/lib/python3.8/site-packages/rest_framework/views.py", line 469, in handle_exception
    self.raise_uncaught_exception(exc)
  File "/home/hernangonzales/projects/test/unico/env/lib/python3.8/site-packages/rest_framework/views.py", line 480, in raise_uncaught_exception
    raise exc
  File "/home/hernangonzales/projects/test/unico/env/lib/python3.8/site-packages/rest_framework/views.py", line 506, in dispatch
    response = handler(request, *args, **kwargs)
  File "/home/hernangonzales/projects/test/unico/env/lib/python3.8/site-packages/rest_framework/generics.py", line 242, in post
    return self.create(request, *args, **kwargs)
  File "/home/hernangonzales/projects/test/unico/env/lib/python3.8/site-packages/rest_framework/mixins.py", line 19, in create
    self.perform_create(serializer)
  File "/home/hernangonzales/projects/test/unico/env/lib/python3.8/site-packages/rest_framework/mixins.py", line 24, in perform_create
    serializer.save()
  File "/home/hernangonzales/projects/test/unico/env/lib/python3.8/site-packages/rest_framework/serializers.py", line 205, in save
    self.instance = self.create(validated_data)
  File "/home/hernangonzales/projects/test/unico/env/lib/python3.8/site-packages/rest_framework/serializers.py", line 939, in create
    instance = ModelClass._default_manager.create(**validated_data)
  File "/home/hernangonzales/projects/test/unico/env/lib/python3.8/site-packages/django/db/models/manager.py", line 85, in manager_method
    return getattr(self.get_queryset(), name)(*args, **kwargs)
  File "/home/hernangonzales/projects/test/unico/env/lib/python3.8/site-packages/django/db/models/query.py", line 447, in create
    obj.save(force_insert=True, using=self.db)
  File "/home/hernangonzales/projects/test/unico/env/lib/python3.8/site-packages/django/db/models/base.py", line 753, in save
    self.save_base(using=using, force_insert=force_insert,
  File "/home/hernangonzales/projects/test/unico/env/lib/python3.8/site-packages/django/db/models/base.py", line 790, in save_base
    updated = self._save_table(
  File "/home/hernangonzales/projects/test/unico/env/lib/python3.8/site-packages/django/db/models/base.py", line 895, in _save_table
    results = self._do_insert(cls._base_manager, using, fields, returning_fields, raw)
  File "/home/hernangonzales/projects/test/unico/env/lib/python3.8/site-packages/django/db/models/base.py", line 933, in _do_insert
    return manager._insert(
  File "/home/hernangonzales/projects/test/unico/env/lib/python3.8/site-packages/django/db/models/manager.py", line 85, in manager_method
    return getattr(self.get_queryset(), name)(*args, **kwargs)
  File "/home/hernangonzales/projects/test/unico/env/lib/python3.8/site-packages/django/db/models/query.py", line 1254, in _insert
    return query.get_compiler(using=using).execute_sql(returning_fields)
  File "/home/hernangonzales/projects/test/unico/env/lib/python3.8/site-packages/django/db/models/sql/compiler.py", line 1397, in execute_sql
    cursor.execute(sql, params)
  File "/home/hernangonzales/projects/test/unico/env/lib/python3.8/site-packages/django/db/backends/utils.py", line 98, in execute
    return super().execute(sql, params)
  File "/home/hernangonzales/projects/test/unico/env/lib/python3.8/site-packages/django/db/backends/utils.py", line 66, in execute
    return self._execute_with_wrappers(sql, params, many=False, executor=self._execute)
  File "/home/hernangonzales/projects/test/unico/env/lib/python3.8/site-packages/django/db/backends/utils.py", line 75, in _execute_with_wrappers
    return executor(sql, params, many, context)
  File "/home/hernangonzales/projects/test/unico/env/lib/python3.8/site-packages/django/db/backends/utils.py", line 84, in _execute
    return self.cursor.execute(sql, params)
  File "/home/hernangonzales/projects/test/unico/env/lib/python3.8/site-packages/django/db/utils.py", line 90, in __exit__
    raise dj_exc_value.with_traceback(traceback) from exc_value
  File "/home/hernangonzales/projects/test/unico/env/lib/python3.8/site-packages/django/db/backends/utils.py", line 84, in _execute
    return self.cursor.execute(sql, params)
django.db.utils.IntegrityError: duplicate key value violates unique constraint "markets_market_pkey"
DETAIL:  Key (id)=(1) already exists.

2021-03-14T17:08:04 HOSTNAME APP_NAME: "POST /markets/ HTTP/1.1" 500 217284
2021-03-14T17:08:19 HOSTNAME APP_NAME: Internal Server Error: /markets/
Traceback (most recent call last):
  File "/home/hernangonzales/projects/test/unico/env/lib/python3.8/site-packages/django/db/backends/utils.py", line 84, in _execute
    return self.cursor.execute(sql, params)
psycopg2.errors.UniqueViolation: duplicate key value violates unique constraint "markets_market_pkey"
DETAIL:  Key (id)=(2) already exists.


The above exception was the direct cause of the following exception:

Traceback (most recent call last):
  File "/home/hernangonzales/projects/test/unico/env/lib/python3.8/site-packages/django/core/handlers/exception.py", line 47, in inner
    response = get_response(request)
  File "/home/hernangonzales/projects/test/unico/env/lib/python3.8/site-packages/django/core/handlers/base.py", line 181, in _get_response
    response = wrapped_callback(request, *callback_args, **callback_kwargs)
  File "/home/hernangonzales/projects/test/unico/env/lib/python3.8/site-packages/django/views/decorators/csrf.py", line 54, in wrapped_view
    return view_func(*args, **kwargs)
  File "/home/hernangonzales/projects/test/unico/env/lib/python3.8/site-packages/django/views/generic/base.py", line 70, in view
    return self.dispatch(request, *args, **kwargs)
  File "/home/hernangonzales/projects/test/unico/env/lib/python3.8/site-packages/rest_framework/views.py", line 509, in dispatch
    response = self.handle_exception(exc)
  File "/home/hernangonzales/projects/test/unico/env/lib/python3.8/site-packages/rest_framework/views.py", line 469, in handle_exception
    self.raise_uncaught_exception(exc)
  File "/home/hernangonzales/projects/test/unico/env/lib/python3.8/site-packages/rest_framework/views.py", line 480, in raise_uncaught_exception
    raise exc
  File "/home/hernangonzales/projects/test/unico/env/lib/python3.8/site-packages/rest_framework/views.py", line 506, in dispatch
    response = handler(request, *args, **kwargs)
  File "/home/hernangonzales/projects/test/unico/env/lib/python3.8/site-packages/rest_framework/generics.py", line 242, in post
    return self.create(request, *args, **kwargs)
  File "/home/hernangonzales/projects/test/unico/env/lib/python3.8/site-packages/rest_framework/mixins.py", line 19, in create
    self.perform_create(serializer)
  File "/home/hernangonzales/projects/test/unico/env/lib/python3.8/site-packages/rest_framework/mixins.py", line 24, in perform_create
    serializer.save()
  File "/home/hernangonzales/projects/test/unico/env/lib/python3.8/site-packages/rest_framework/serializers.py", line 205, in save
    self.instance = self.create(validated_data)
  File "/home/hernangonzales/projects/test/unico/env/lib/python3.8/site-packages/rest_framework/serializers.py", line 939, in create
    instance = ModelClass._default_manager.create(**validated_data)
  File "/home/hernangonzales/projects/test/unico/env/lib/python3.8/site-packages/django/db/models/manager.py", line 85, in manager_method
    return getattr(self.get_queryset(), name)(*args, **kwargs)
  File "/home/hernangonzales/projects/test/unico/env/lib/python3.8/site-packages/django/db/models/query.py", line 447, in create
    obj.save(force_insert=True, using=self.db)
  File "/home/hernangonzales/projects/test/unico/env/lib/python3.8/site-packages/django/db/models/base.py", line 753, in save
    self.save_base(using=using, force_insert=force_insert,
  File "/home/hernangonzales/projects/test/unico/env/lib/python3.8/site-packages/django/db/models/base.py", line 790, in save_base
    updated = self._save_table(
  File "/home/hernangonzales/projects/test/unico/env/lib/python3.8/site-packages/django/db/models/base.py", line 895, in _save_table
    results = self._do_insert(cls._base_manager, using, fields, returning_fields, raw)
  File "/home/hernangonzales/projects/test/unico/env/lib/python3.8/site-packages/django/db/models/base.py", line 933, in _do_insert
    return manager._insert(
  File "/home/hernangonzales/projects/test/unico/env/lib/python3.8/site-packages/django/db/models/manager.py", line 85, in manager_method
    return getattr(self.get_queryset(), name)(*args, **kwargs)
  File "/home/hernangonzales/projects/test/unico/env/lib/python3.8/site-packages/django/db/models/query.py", line 1254, in _insert
    return query.get_compiler(using=using).execute_sql(returning_fields)
  File "/home/hernangonzales/projects/test/unico/env/lib/python3.8/site-packages/django/db/models/sql/compiler.py", line 1397, in execute_sql
    cursor.execute(sql, params)
  File "/home/hernangonzales/projects/test/unico/env/lib/python3.8/site-packages/django/db/backends/utils.py", line 98, in execute
    return super().execute(sql, params)
  File "/home/hernangonzales/projects/test/unico/env/lib/python3.8/site-packages/django/db/backends/utils.py", line 66, in execute
    return self._execute_with_wrappers(sql, params, many=False, executor=self._execute)
  File "/home/hernangonzales/projects/test/unico/env/lib/python3.8/site-packages/django/db/backends/utils.py", line 75, in _execute_with_wrappers
    return executor(sql, params, many, context)
  File "/home/hernangonzales/projects/test/unico/env/lib/python3.8/site-packages/django/db/backends/utils.py", line 84, in _execute
    return self.cursor.execute(sql, params)
  File "/home/hernangonzales/projects/test/unico/env/lib/python3.8/site-packages/django/db/utils.py", line 90, in __exit__
    raise dj_exc_value.with_traceback(traceback) from exc_value
  File "/home/hernangonzales/projects/test/unico/env/lib/python3.8/site-packages/django/db/backends/utils.py", line 84, in _execute
    return self.cursor.execute(sql, params)
django.db.utils.IntegrityError: duplicate key value violates unique constraint "markets_market_pkey"
DETAIL:  Key (id)=(2) already exists.

2021-03-14T17:08:19 HOSTNAME APP_NAME: "POST /markets/ HTTP/1.1" 500 217284
2021-03-14T17:09:20 HOSTNAME APP_NAME: Internal Server Error: /markets/
Traceback (most recent call last):
  File "/home/hernangonzales/projects/test/unico/env/lib/python3.8/site-packages/django/db/backends/utils.py", line 84, in _execute
    return self.cursor.execute(sql, params)
psycopg2.errors.UniqueViolation: duplicate key value violates unique constraint "markets_market_pkey"
DETAIL:  Key (id)=(3) already exists.


The above exception was the direct cause of the following exception:

Traceback (most recent call last):
  File "/home/hernangonzales/projects/test/unico/env/lib/python3.8/site-packages/django/core/handlers/exception.py", line 47, in inner
    response = get_response(request)
  File "/home/hernangonzales/projects/test/unico/env/lib/python3.8/site-packages/django/core/handlers/base.py", line 181, in _get_response
    response = wrapped_callback(request, *callback_args, **callback_kwargs)
  File "/home/hernangonzales/projects/test/unico/env/lib/python3.8/site-packages/django/views/decorators/csrf.py", line 54, in wrapped_view
    return view_func(*args, **kwargs)
  File "/home/hernangonzales/projects/test/unico/env/lib/python3.8/site-packages/django/views/generic/base.py", line 70, in view
    return self.dispatch(request, *args, **kwargs)
  File "/home/hernangonzales/projects/test/unico/env/lib/python3.8/site-packages/rest_framework/views.py", line 509, in dispatch
    response = self.handle_exception(exc)
  File "/home/hernangonzales/projects/test/unico/env/lib/python3.8/site-packages/rest_framework/views.py", line 469, in handle_exception
    self.raise_uncaught_exception(exc)
  File "/home/hernangonzales/projects/test/unico/env/lib/python3.8/site-packages/rest_framework/views.py", line 480, in raise_uncaught_exception
    raise exc
  File "/home/hernangonzales/projects/test/unico/env/lib/python3.8/site-packages/rest_framework/views.py", line 506, in dispatch
    response = handler(request, *args, **kwargs)
  File "/home/hernangonzales/projects/test/unico/env/lib/python3.8/site-packages/rest_framework/generics.py", line 242, in post
    return self.create(request, *args, **kwargs)
  File "/home/hernangonzales/projects/test/unico/env/lib/python3.8/site-packages/rest_framework/mixins.py", line 19, in create
    self.perform_create(serializer)
  File "/home/hernangonzales/projects/test/unico/env/lib/python3.8/site-packages/rest_framework/mixins.py", line 24, in perform_create
    serializer.save()
  File "/home/hernangonzales/projects/test/unico/env/lib/python3.8/site-packages/rest_framework/serializers.py", line 205, in save
    self.instance = self.create(validated_data)
  File "/home/hernangonzales/projects/test/unico/env/lib/python3.8/site-packages/rest_framework/serializers.py", line 939, in create
    instance = ModelClass._default_manager.create(**validated_data)
  File "/home/hernangonzales/projects/test/unico/env/lib/python3.8/site-packages/django/db/models/manager.py", line 85, in manager_method
    return getattr(self.get_queryset(), name)(*args, **kwargs)
  File "/home/hernangonzales/projects/test/unico/env/lib/python3.8/site-packages/django/db/models/query.py", line 447, in create
    obj.save(force_insert=True, using=self.db)
  File "/home/hernangonzales/projects/test/unico/env/lib/python3.8/site-packages/django/db/models/base.py", line 753, in save
    self.save_base(using=using, force_insert=force_insert,
  File "/home/hernangonzales/projects/test/unico/env/lib/python3.8/site-packages/django/db/models/base.py", line 790, in save_base
    updated = self._save_table(
  File "/home/hernangonzales/projects/test/unico/env/lib/python3.8/site-packages/django/db/models/base.py", line 895, in _save_table
    results = self._do_insert(cls._base_manager, using, fields, returning_fields, raw)
  File "/home/hernangonzales/projects/test/unico/env/lib/python3.8/site-packages/django/db/models/base.py", line 933, in _do_insert
    return manager._insert(
  File "/home/hernangonzales/projects/test/unico/env/lib/python3.8/site-packages/django/db/models/manager.py", line 85, in manager_method
    return getattr(self.get_queryset(), name)(*args, **kwargs)
  File "/home/hernangonzales/projects/test/unico/env/lib/python3.8/site-packages/django/db/models/query.py", line 1254, in _insert
    return query.get_compiler(using=using).execute_sql(returning_fields)
  File "/home/hernangonzales/projects/test/unico/env/lib/python3.8/site-packages/django/db/models/sql/compiler.py", line 1397, in execute_sql
    cursor.execute(sql, params)
  File "/home/hernangonzales/projects/test/unico/env/lib/python3.8/site-packages/django/db/backends/utils.py", line 98, in execute
    return super().execute(sql, params)
  File "/home/hernangonzales/projects/test/unico/env/lib/python3.8/site-packages/django/db/backends/utils.py", line 66, in execute
    return self._execute_with_wrappers(sql, params, many=False, executor=self._execute)
  File "/home/hernangonzales/projects/test/unico/env/lib/python3.8/site-packages/django/db/backends/utils.py", line 75, in _execute_with_wrappers
    return executor(sql, params, many, context)
  File "/home/hernangonzales/projects/test/unico/env/lib/python3.8/site-packages/django/db/backends/utils.py", line 84, in _execute
    return self.cursor.execute(sql, params)
  File "/home/hernangonzales/projects/test/unico/env/lib/python3.8/site-packages/django/db/utils.py", line 90, in __exit__
    raise dj_exc_value.with_traceback(traceback) from exc_value
  File "/home/hernangonzales/projects/test/unico/env/lib/python3.8/site-packages/django/db/backends/utils.py", line 84, in _execute
    return self.cursor.execute(sql, params)
django.db.utils.IntegrityError: duplicate key value violates unique constraint "markets_market_pkey"
DETAIL:  Key (id)=(3) already exists.

2021-03-14T17:09:20 HOSTNAME APP_NAME: "POST /markets/ HTTP/1.1" 500 217284
2021-03-14T17:09:43 HOSTNAME APP_NAME: Bad Request: /markets/
2021-03-14T17:09:43 HOSTNAME APP_NAME: "POST /markets/ HTTP/1.1" 400 71
2021-03-14T17:09:55 HOSTNAME APP_NAME: Internal Server Error: /markets/
Traceback (most recent call last):
  File "/home/hernangonzales/projects/test/unico/env/lib/python3.8/site-packages/django/db/backends/utils.py", line 84, in _execute
    return self.cursor.execute(sql, params)
psycopg2.errors.UniqueViolation: duplicate key value violates unique constraint "markets_market_pkey"
DETAIL:  Key (id)=(4) already exists.


The above exception was the direct cause of the following exception:

Traceback (most recent call last):
  File "/home/hernangonzales/projects/test/unico/env/lib/python3.8/site-packages/django/core/handlers/exception.py", line 47, in inner
    response = get_response(request)
  File "/home/hernangonzales/projects/test/unico/env/lib/python3.8/site-packages/django/core/handlers/base.py", line 181, in _get_response
    response = wrapped_callback(request, *callback_args, **callback_kwargs)
  File "/home/hernangonzales/projects/test/unico/env/lib/python3.8/site-packages/django/views/decorators/csrf.py", line 54, in wrapped_view
    return view_func(*args, **kwargs)
  File "/home/hernangonzales/projects/test/unico/env/lib/python3.8/site-packages/django/views/generic/base.py", line 70, in view
    return self.dispatch(request, *args, **kwargs)
  File "/home/hernangonzales/projects/test/unico/env/lib/python3.8/site-packages/rest_framework/views.py", line 509, in dispatch
    response = self.handle_exception(exc)
  File "/home/hernangonzales/projects/test/unico/env/lib/python3.8/site-packages/rest_framework/views.py", line 469, in handle_exception
    self.raise_uncaught_exception(exc)
  File "/home/hernangonzales/projects/test/unico/env/lib/python3.8/site-packages/rest_framework/views.py", line 480, in raise_uncaught_exception
    raise exc
  File "/home/hernangonzales/projects/test/unico/env/lib/python3.8/site-packages/rest_framework/views.py", line 506, in dispatch
    response = handler(request, *args, **kwargs)
  File "/home/hernangonzales/projects/test/unico/env/lib/python3.8/site-packages/rest_framework/generics.py", line 242, in post
    return self.create(request, *args, **kwargs)
  File "/home/hernangonzales/projects/test/unico/env/lib/python3.8/site-packages/rest_framework/mixins.py", line 19, in create
    self.perform_create(serializer)
  File "/home/hernangonzales/projects/test/unico/env/lib/python3.8/site-packages/rest_framework/mixins.py", line 24, in perform_create
    serializer.save()
  File "/home/hernangonzales/projects/test/unico/env/lib/python3.8/site-packages/rest_framework/serializers.py", line 205, in save
    self.instance = self.create(validated_data)
  File "/home/hernangonzales/projects/test/unico/env/lib/python3.8/site-packages/rest_framework/serializers.py", line 939, in create
    instance = ModelClass._default_manager.create(**validated_data)
  File "/home/hernangonzales/projects/test/unico/env/lib/python3.8/site-packages/django/db/models/manager.py", line 85, in manager_method
    return getattr(self.get_queryset(), name)(*args, **kwargs)
  File "/home/hernangonzales/projects/test/unico/env/lib/python3.8/site-packages/django/db/models/query.py", line 447, in create
    obj.save(force_insert=True, using=self.db)
  File "/home/hernangonzales/projects/test/unico/env/lib/python3.8/site-packages/django/db/models/base.py", line 753, in save
    self.save_base(using=using, force_insert=force_insert,
  File "/home/hernangonzales/projects/test/unico/env/lib/python3.8/site-packages/django/db/models/base.py", line 790, in save_base
    updated = self._save_table(
  File "/home/hernangonzales/projects/test/unico/env/lib/python3.8/site-packages/django/db/models/base.py", line 895, in _save_table
    results = self._do_insert(cls._base_manager, using, fields, returning_fields, raw)
  File "/home/hernangonzales/projects/test/unico/env/lib/python3.8/site-packages/django/db/models/base.py", line 933, in _do_insert
    return manager._insert(
  File "/home/hernangonzales/projects/test/unico/env/lib/python3.8/site-packages/django/db/models/manager.py", line 85, in manager_method
    return getattr(self.get_queryset(), name)(*args, **kwargs)
  File "/home/hernangonzales/projects/test/unico/env/lib/python3.8/site-packages/django/db/models/query.py", line 1254, in _insert
    return query.get_compiler(using=using).execute_sql(returning_fields)
  File "/home/hernangonzales/projects/test/unico/env/lib/python3.8/site-packages/django/db/models/sql/compiler.py", line 1397, in execute_sql
    cursor.execute(sql, params)
  File "/home/hernangonzales/projects/test/unico/env/lib/python3.8/site-packages/django/db/backends/utils.py", line 98, in execute
    return super().execute(sql, params)
  File "/home/hernangonzales/projects/test/unico/env/lib/python3.8/site-packages/django/db/backends/utils.py", line 66, in execute
    return self._execute_with_wrappers(sql, params, many=False, executor=self._execute)
  File "/home/hernangonzales/projects/test/unico/env/lib/python3.8/site-packages/django/db/backends/utils.py", line 75, in _execute_with_wrappers
    return executor(sql, params, many, context)
  File "/home/hernangonzales/projects/test/unico/env/lib/python3.8/site-packages/django/db/backends/utils.py", line 84, in _execute
    return self.cursor.execute(sql, params)
  File "/home/hernangonzales/projects/test/unico/env/lib/python3.8/site-packages/django/db/utils.py", line 90, in __exit__
    raise dj_exc_value.with_traceback(traceback) from exc_value
  File "/home/hernangonzales/projects/test/unico/env/lib/python3.8/site-packages/django/db/backends/utils.py", line 84, in _execute
    return self.cursor.execute(sql, params)
django.db.utils.IntegrityError: duplicate key value violates unique constraint "markets_market_pkey"
DETAIL:  Key (id)=(4) already exists.

2021-03-14T17:09:55 HOSTNAME APP_NAME: "POST /markets/ HTTP/1.1" 500 217074
2021-03-15T09:03:08 HOSTNAME APP_NAME: Watching for file changes with StatReloader
2021-03-15T09:08:08 HOSTNAME APP_NAME: Watching for file changes with StatReloader
2021-03-15T09:08:13 HOSTNAME APP_NAME: Internal Server Error: /markets/
Traceback (most recent call last):
  File "/home/hernangonzales/projects/test/unico/env/lib/python3.8/site-packages/django/db/backends/utils.py", line 84, in _execute
    return self.cursor.execute(sql, params)
psycopg2.errors.UniqueViolation: duplicate key value violates unique constraint "markets_market_pkey"
DETAIL:  Key (id)=(1) already exists.


The above exception was the direct cause of the following exception:

Traceback (most recent call last):
  File "/home/hernangonzales/projects/test/unico/env/lib/python3.8/site-packages/django/core/handlers/exception.py", line 47, in inner
    response = get_response(request)
  File "/home/hernangonzales/projects/test/unico/env/lib/python3.8/site-packages/django/core/handlers/base.py", line 181, in _get_response
    response = wrapped_callback(request, *callback_args, **callback_kwargs)
  File "/home/hernangonzales/projects/test/unico/env/lib/python3.8/site-packages/django/views/decorators/csrf.py", line 54, in wrapped_view
    return view_func(*args, **kwargs)
  File "/home/hernangonzales/projects/test/unico/env/lib/python3.8/site-packages/django/views/generic/base.py", line 70, in view
    return self.dispatch(request, *args, **kwargs)
  File "/home/hernangonzales/projects/test/unico/env/lib/python3.8/site-packages/rest_framework/views.py", line 509, in dispatch
    response = self.handle_exception(exc)
  File "/home/hernangonzales/projects/test/unico/env/lib/python3.8/site-packages/rest_framework/views.py", line 469, in handle_exception
    self.raise_uncaught_exception(exc)
  File "/home/hernangonzales/projects/test/unico/env/lib/python3.8/site-packages/rest_framework/views.py", line 480, in raise_uncaught_exception
    raise exc
  File "/home/hernangonzales/projects/test/unico/env/lib/python3.8/site-packages/rest_framework/views.py", line 506, in dispatch
    response = handler(request, *args, **kwargs)
  File "/home/hernangonzales/projects/test/unico/env/lib/python3.8/site-packages/rest_framework/generics.py", line 242, in post
    return self.create(request, *args, **kwargs)
  File "/home/hernangonzales/projects/test/unico/env/lib/python3.8/site-packages/rest_framework/mixins.py", line 19, in create
    self.perform_create(serializer)
  File "/home/hernangonzales/projects/test/unico/env/lib/python3.8/site-packages/rest_framework/mixins.py", line 24, in perform_create
    serializer.save()
  File "/home/hernangonzales/projects/test/unico/env/lib/python3.8/site-packages/rest_framework/serializers.py", line 205, in save
    self.instance = self.create(validated_data)
  File "/home/hernangonzales/projects/test/unico/env/lib/python3.8/site-packages/rest_framework/serializers.py", line 939, in create
    instance = ModelClass._default_manager.create(**validated_data)
  File "/home/hernangonzales/projects/test/unico/env/lib/python3.8/site-packages/django/db/models/manager.py", line 85, in manager_method
    return getattr(self.get_queryset(), name)(*args, **kwargs)
  File "/home/hernangonzales/projects/test/unico/env/lib/python3.8/site-packages/django/db/models/query.py", line 447, in create
    obj.save(force_insert=True, using=self.db)
  File "/home/hernangonzales/projects/test/unico/env/lib/python3.8/site-packages/django/db/models/base.py", line 753, in save
    self.save_base(using=using, force_insert=force_insert,
  File "/home/hernangonzales/projects/test/unico/env/lib/python3.8/site-packages/django/db/models/base.py", line 790, in save_base
    updated = self._save_table(
  File "/home/hernangonzales/projects/test/unico/env/lib/python3.8/site-packages/django/db/models/base.py", line 895, in _save_table
    results = self._do_insert(cls._base_manager, using, fields, returning_fields, raw)
  File "/home/hernangonzales/projects/test/unico/env/lib/python3.8/site-packages/django/db/models/base.py", line 933, in _do_insert
    return manager._insert(
  File "/home/hernangonzales/projects/test/unico/env/lib/python3.8/site-packages/django/db/models/manager.py", line 85, in manager_method
    return getattr(self.get_queryset(), name)(*args, **kwargs)
  File "/home/hernangonzales/projects/test/unico/env/lib/python3.8/site-packages/django/db/models/query.py", line 1254, in _insert
    return query.get_compiler(using=using).execute_sql(returning_fields)
  File "/home/hernangonzales/projects/test/unico/env/lib/python3.8/site-packages/django/db/models/sql/compiler.py", line 1397, in execute_sql
    cursor.execute(sql, params)
  File "/home/hernangonzales/projects/test/unico/env/lib/python3.8/site-packages/django/db/backends/utils.py", line 98, in execute
    return super().execute(sql, params)
  File "/home/hernangonzales/projects/test/unico/env/lib/python3.8/site-packages/django/db/backends/utils.py", line 66, in execute
    return self._execute_with_wrappers(sql, params, many=False, executor=self._execute)
  File "/home/hernangonzales/projects/test/unico/env/lib/python3.8/site-packages/django/db/backends/utils.py", line 75, in _execute_with_wrappers
    return executor(sql, params, many, context)
  File "/home/hernangonzales/projects/test/unico/env/lib/python3.8/site-packages/django/db/backends/utils.py", line 84, in _execute
    return self.cursor.execute(sql, params)
  File "/home/hernangonzales/projects/test/unico/env/lib/python3.8/site-packages/django/db/utils.py", line 90, in __exit__
    raise dj_exc_value.with_traceback(traceback) from exc_value
  File "/home/hernangonzales/projects/test/unico/env/lib/python3.8/site-packages/django/db/backends/utils.py", line 84, in _execute
    return self.cursor.execute(sql, params)
django.db.utils.IntegrityError: duplicate key value violates unique constraint "markets_market_pkey"
DETAIL:  Key (id)=(1) already exists.

2021-03-15T09:08:13 HOSTNAME APP_NAME: "POST /markets/ HTTP/1.1" 500 217074
2021-03-15T09:25:24 HOSTNAME APP_NAME: Watching for file changes with StatReloader
2021-03-15T09:32:15 HOSTNAME APP_NAME: Watching for file changes with StatReloader
2021-03-15T09:32:46 HOSTNAME APP_NAME: Watching for file changes with StatReloader
2021-03-15T09:49:55 HOSTNAME APP_NAME: Watching for file changes with StatReloader
2021-03-15T09:51:57 HOSTNAME APP_NAME: Watching for file changes with StatReloader
2021-03-15T09:52:38 HOSTNAME APP_NAME: Watching for file changes with StatReloader
2021-03-15T09:53:24 HOSTNAME APP_NAME: Watching for file changes with StatReloader
2021-03-15T09:53:26 HOSTNAME APP_NAME: "POST /markets/ HTTP/1.1" 201 392
2021-03-15T09:54:01 HOSTNAME APP_NAME: "POST /markets/ HTTP/1.1" 201 371
2021-03-15T09:54:13 HOSTNAME APP_NAME: "GET /markets?district=BRAS HTTP/1.1" 301 0
2021-03-15T09:54:13 HOSTNAME APP_NAME: "GET /markets/?district=BRAS HTTP/1.1" 200 2767
2021-03-15T09:54:23 HOSTNAME APP_NAME: "GET /markets?district=BRAS&region_5=asd HTTP/1.1" 301 0
2021-03-15T09:54:23 HOSTNAME APP_NAME: "GET /markets/?district=BRAS&region_5=asd HTTP/1.1" 200 2
2021-03-15T09:54:28 HOSTNAME APP_NAME: "GET /markets?district=BRAS&region_5=Leste HTTP/1.1" 301 0
2021-03-15T09:54:28 HOSTNAME APP_NAME: "GET /markets/?district=BRAS&region_5=Leste HTTP/1.1" 200 2767
2021-03-15T09:54:36 HOSTNAME APP_NAME: "GET /markets?district=BRAS HTTP/1.1" 301 0
2021-03-15T09:54:36 HOSTNAME APP_NAME: "GET /markets/?district=BRAS HTTP/1.1" 200 2767
2021-03-15T09:54:47 HOSTNAME APP_NAME: "GET /markets HTTP/1.1" 301 0
2021-03-15T09:54:47 HOSTNAME APP_NAME: "GET /markets/ HTTP/1.1" 200 367259
2021-03-15T09:55:19 HOSTNAME APP_NAME: "GET /markets?region_5=Leste HTTP/1.1" 301 0
2021-03-15T09:55:19 HOSTNAME APP_NAME: "GET /markets/?region_5=Leste HTTP/1.1" 200 150246
2021-03-15T09:56:01 HOSTNAME APP_NAME: /home/hernangonzales/projects/test/unico/markets/views.py changed, reloading.
2021-03-15T09:56:04 HOSTNAME APP_NAME: Watching for file changes with StatReloader
2021-03-15T09:56:21 HOSTNAME APP_NAME: "GET /markets?region_5=Leste&address_city=BRAS HTTP/1.1" 301 0
2021-03-15T09:56:21 HOSTNAME APP_NAME: "GET /markets/?region_5=Leste&address_city=BRAS HTTP/1.1" 200 1955
2021-03-15T09:57:05 HOSTNAME APP_NAME: "POST /markets/ HTTP/1.1" 201 371
2021-03-15T09:59:07 HOSTNAME APP_NAME: "POST /markets/ HTTP/1.1" 201 371
2021-03-15T09:59:16 HOSTNAME APP_NAME: "POST /markets/ HTTP/1.1" 201 371
2021-03-15T09:59:21 HOSTNAME APP_NAME: Not Found: /markets/4003-7
2021-03-15T09:59:21 HOSTNAME APP_NAME: "PUT /markets/4003-7 HTTP/1.1" 404 23
2021-03-15T09:59:33 HOSTNAME APP_NAME: Not Found: /markets/4003-7
2021-03-15T09:59:33 HOSTNAME APP_NAME: "PUT /markets/4003-7 HTTP/1.1" 404 23
2021-03-15T09:59:39 HOSTNAME APP_NAME: Not Found: /markets/4003-7
2021-03-15T09:59:39 HOSTNAME APP_NAME: "PUT /markets/4003-7 HTTP/1.1" 404 23
2021-03-15T09:59:54 HOSTNAME APP_NAME: Not Found: /markets/4003-7
2021-03-15T09:59:54 HOSTNAME APP_NAME: "PUT /markets/4003-7 HTTP/1.1" 404 23
2021-03-15T10:00:12 HOSTNAME APP_NAME: Not Found: /markets/4003-7
2021-03-15T10:00:12 HOSTNAME APP_NAME: "DELETE /markets/4003-7 HTTP/1.1" 404 23
2021-03-15T10:00:15 HOSTNAME APP_NAME: Not Found: /markets/40037
2021-03-15T10:00:15 HOSTNAME APP_NAME: "DELETE /markets/40037 HTTP/1.1" 404 23
2021-03-15T10:00:55 HOSTNAME APP_NAME: "GET /markets?district=BRAS HTTP/1.1" 301 0
2021-03-15T10:00:55 HOSTNAME APP_NAME: "GET /markets/?district=BRAS HTTP/1.1" 200 3883
2021-03-15T10:01:05 HOSTNAME APP_NAME: Not Found: /markets/4003-7
2021-03-15T10:01:05 HOSTNAME APP_NAME: "DELETE /markets/4003-7 HTTP/1.1" 404 23
2021-03-15T10:01:57 HOSTNAME APP_NAME: /home/hernangonzales/projects/test/unico/markets/views.py changed, reloading.
2021-03-15T10:01:57 HOSTNAME APP_NAME: Watching for file changes with StatReloader
2021-03-15T10:02:01 HOSTNAME APP_NAME: Watching for file changes with StatReloader
2021-03-15T10:02:03 HOSTNAME APP_NAME: Internal Server Error: /markets/4003-7
Traceback (most recent call last):
  File "/home/hernangonzales/projects/test/unico/env/lib/python3.8/site-packages/django/core/handlers/exception.py", line 47, in inner
    response = get_response(request)
  File "/home/hernangonzales/projects/test/unico/env/lib/python3.8/site-packages/django/core/handlers/base.py", line 181, in _get_response
    response = wrapped_callback(request, *callback_args, **callback_kwargs)
  File "/home/hernangonzales/projects/test/unico/env/lib/python3.8/site-packages/django/views/decorators/csrf.py", line 54, in wrapped_view
    return view_func(*args, **kwargs)
  File "/home/hernangonzales/projects/test/unico/env/lib/python3.8/site-packages/django/views/generic/base.py", line 70, in view
    return self.dispatch(request, *args, **kwargs)
  File "/home/hernangonzales/projects/test/unico/env/lib/python3.8/site-packages/rest_framework/views.py", line 509, in dispatch
    response = self.handle_exception(exc)
  File "/home/hernangonzales/projects/test/unico/env/lib/python3.8/site-packages/rest_framework/views.py", line 469, in handle_exception
    self.raise_uncaught_exception(exc)
  File "/home/hernangonzales/projects/test/unico/env/lib/python3.8/site-packages/rest_framework/views.py", line 480, in raise_uncaught_exception
    raise exc
  File "/home/hernangonzales/projects/test/unico/env/lib/python3.8/site-packages/rest_framework/views.py", line 506, in dispatch
    response = handler(request, *args, **kwargs)
  File "/home/hernangonzales/projects/test/unico/env/lib/python3.8/site-packages/rest_framework/generics.py", line 291, in delete
    return self.destroy(request, *args, **kwargs)
  File "/home/hernangonzales/projects/test/unico/env/lib/python3.8/site-packages/rest_framework/mixins.py", line 90, in destroy
    instance = self.get_object()
  File "/home/hernangonzales/projects/test/unico/env/lib/python3.8/site-packages/rest_framework/generics.py", line 96, in get_object
    obj = get_object_or_404(queryset, **filter_kwargs)
  File "/home/hernangonzales/projects/test/unico/env/lib/python3.8/site-packages/rest_framework/generics.py", line 19, in get_object_or_404
    return _get_object_or_404(queryset, *filter_args, **filter_kwargs)
  File "/home/hernangonzales/projects/test/unico/env/lib/python3.8/site-packages/django/shortcuts.py", line 76, in get_object_or_404
    return queryset.get(*args, **kwargs)
  File "/home/hernangonzales/projects/test/unico/env/lib/python3.8/site-packages/django/db/models/query.py", line 433, in get
    raise self.model.MultipleObjectsReturned(
markets.models.Market.MultipleObjectsReturned: get() returned more than one Market -- it returned 6!
2021-03-15T10:02:03 HOSTNAME APP_NAME: "DELETE /markets/4003-7 HTTP/1.1" 500 117086
2021-03-15T10:02:12 HOSTNAME APP_NAME: Internal Server Error: /markets/4003-7
Traceback (most recent call last):
  File "/home/hernangonzales/projects/test/unico/env/lib/python3.8/site-packages/django/core/handlers/exception.py", line 47, in inner
    response = get_response(request)
  File "/home/hernangonzales/projects/test/unico/env/lib/python3.8/site-packages/django/core/handlers/base.py", line 181, in _get_response
    response = wrapped_callback(request, *callback_args, **callback_kwargs)
  File "/home/hernangonzales/projects/test/unico/env/lib/python3.8/site-packages/django/views/decorators/csrf.py", line 54, in wrapped_view
    return view_func(*args, **kwargs)
  File "/home/hernangonzales/projects/test/unico/env/lib/python3.8/site-packages/django/views/generic/base.py", line 70, in view
    return self.dispatch(request, *args, **kwargs)
  File "/home/hernangonzales/projects/test/unico/env/lib/python3.8/site-packages/rest_framework/views.py", line 509, in dispatch
    response = self.handle_exception(exc)
  File "/home/hernangonzales/projects/test/unico/env/lib/python3.8/site-packages/rest_framework/views.py", line 469, in handle_exception
    self.raise_uncaught_exception(exc)
  File "/home/hernangonzales/projects/test/unico/env/lib/python3.8/site-packages/rest_framework/views.py", line 480, in raise_uncaught_exception
    raise exc
  File "/home/hernangonzales/projects/test/unico/env/lib/python3.8/site-packages/rest_framework/views.py", line 506, in dispatch
    response = handler(request, *args, **kwargs)
  File "/home/hernangonzales/projects/test/unico/env/lib/python3.8/site-packages/rest_framework/generics.py", line 291, in delete
    return self.destroy(request, *args, **kwargs)
  File "/home/hernangonzales/projects/test/unico/env/lib/python3.8/site-packages/rest_framework/mixins.py", line 90, in destroy
    instance = self.get_object()
  File "/home/hernangonzales/projects/test/unico/env/lib/python3.8/site-packages/rest_framework/generics.py", line 96, in get_object
    obj = get_object_or_404(queryset, **filter_kwargs)
  File "/home/hernangonzales/projects/test/unico/env/lib/python3.8/site-packages/rest_framework/generics.py", line 19, in get_object_or_404
    return _get_object_or_404(queryset, *filter_args, **filter_kwargs)
  File "/home/hernangonzales/projects/test/unico/env/lib/python3.8/site-packages/django/shortcuts.py", line 76, in get_object_or_404
    return queryset.get(*args, **kwargs)
  File "/home/hernangonzales/projects/test/unico/env/lib/python3.8/site-packages/django/db/models/query.py", line 433, in get
    raise self.model.MultipleObjectsReturned(
markets.models.Market.MultipleObjectsReturned: get() returned more than one Market -- it returned 6!
2021-03-15T10:02:12 HOSTNAME APP_NAME: "DELETE /markets/4003-7 HTTP/1.1" 500 117086
2021-03-15T10:16:51 HOSTNAME APP_NAME: /home/hernangonzales/projects/test/unico/markets/models.py changed, reloading.
2021-03-15T10:16:51 HOSTNAME APP_NAME: Watching for file changes with StatReloader
2021-03-15T10:17:13 HOSTNAME APP_NAME: Watching for file changes with StatReloader
2021-03-15T10:17:37 HOSTNAME APP_NAME: Watching for file changes with StatReloader
2021-03-15T10:18:27 HOSTNAME APP_NAME: Watching for file changes with StatReloader
2021-03-15T10:19:00 HOSTNAME APP_NAME: Watching for file changes with StatReloader
2021-03-15T10:19:05 HOSTNAME APP_NAME: "GET /markets?district=BRAS HTTP/1.1" 301 0
2021-03-15T10:19:05 HOSTNAME APP_NAME: "GET /markets/?district=BRAS HTTP/1.1" 200 2047
2021-03-15T10:19:17 HOSTNAME APP_NAME: Internal Server Error: /markets/4003-7
Traceback (most recent call last):
  File "/home/hernangonzales/projects/test/unico/env/lib/python3.8/site-packages/django/core/handlers/exception.py", line 47, in inner
    response = get_response(request)
  File "/home/hernangonzales/projects/test/unico/env/lib/python3.8/site-packages/django/core/handlers/base.py", line 181, in _get_response
    response = wrapped_callback(request, *callback_args, **callback_kwargs)
  File "/home/hernangonzales/projects/test/unico/env/lib/python3.8/site-packages/django/views/decorators/csrf.py", line 54, in wrapped_view
    return view_func(*args, **kwargs)
  File "/home/hernangonzales/projects/test/unico/env/lib/python3.8/site-packages/django/views/generic/base.py", line 70, in view
    return self.dispatch(request, *args, **kwargs)
  File "/home/hernangonzales/projects/test/unico/env/lib/python3.8/site-packages/rest_framework/views.py", line 509, in dispatch
    response = self.handle_exception(exc)
  File "/home/hernangonzales/projects/test/unico/env/lib/python3.8/site-packages/rest_framework/views.py", line 469, in handle_exception
    self.raise_uncaught_exception(exc)
  File "/home/hernangonzales/projects/test/unico/env/lib/python3.8/site-packages/rest_framework/views.py", line 480, in raise_uncaught_exception
    raise exc
  File "/home/hernangonzales/projects/test/unico/env/lib/python3.8/site-packages/rest_framework/views.py", line 506, in dispatch
    response = handler(request, *args, **kwargs)
  File "/home/hernangonzales/projects/test/unico/env/lib/python3.8/site-packages/rest_framework/generics.py", line 291, in delete
    return self.destroy(request, *args, **kwargs)
  File "/home/hernangonzales/projects/test/unico/env/lib/python3.8/site-packages/rest_framework/mixins.py", line 90, in destroy
    instance = self.get_object()
  File "/home/hernangonzales/projects/test/unico/env/lib/python3.8/site-packages/rest_framework/generics.py", line 96, in get_object
    obj = get_object_or_404(queryset, **filter_kwargs)
  File "/home/hernangonzales/projects/test/unico/env/lib/python3.8/site-packages/rest_framework/generics.py", line 19, in get_object_or_404
    return _get_object_or_404(queryset, *filter_args, **filter_kwargs)
  File "/home/hernangonzales/projects/test/unico/env/lib/python3.8/site-packages/django/shortcuts.py", line 76, in get_object_or_404
    return queryset.get(*args, **kwargs)
  File "/home/hernangonzales/projects/test/unico/env/lib/python3.8/site-packages/django/db/models/query.py", line 418, in get
    clone = self._chain() if self.query.combinator else self.filter(*args, **kwargs)
  File "/home/hernangonzales/projects/test/unico/env/lib/python3.8/site-packages/django/db/models/query.py", line 942, in filter
    return self._filter_or_exclude(False, *args, **kwargs)
  File "/home/hernangonzales/projects/test/unico/env/lib/python3.8/site-packages/django/db/models/query.py", line 962, in _filter_or_exclude
    clone._filter_or_exclude_inplace(negate, *args, **kwargs)
  File "/home/hernangonzales/projects/test/unico/env/lib/python3.8/site-packages/django/db/models/query.py", line 969, in _filter_or_exclude_inplace
    self._query.add_q(Q(*args, **kwargs))
  File "/home/hernangonzales/projects/test/unico/env/lib/python3.8/site-packages/django/db/models/sql/query.py", line 1358, in add_q
    clause, _ = self._add_q(q_object, self.used_aliases)
  File "/home/hernangonzales/projects/test/unico/env/lib/python3.8/site-packages/django/db/models/sql/query.py", line 1377, in _add_q
    child_clause, needed_inner = self.build_filter(
  File "/home/hernangonzales/projects/test/unico/env/lib/python3.8/site-packages/django/db/models/sql/query.py", line 1258, in build_filter
    lookups, parts, reffed_expression = self.solve_lookup_type(arg)
  File "/home/hernangonzales/projects/test/unico/env/lib/python3.8/site-packages/django/db/models/sql/query.py", line 1084, in solve_lookup_type
    _, field, _, lookup_parts = self.names_to_path(lookup_splitted, self.get_meta())
  File "/home/hernangonzales/projects/test/unico/env/lib/python3.8/site-packages/django/db/models/sql/query.py", line 1481, in names_to_path
    raise FieldError("Cannot resolve keyword '%s' into field. "
django.core.exceptions.FieldError: Cannot resolve keyword 'registry' into field. Choices are: address_city, address_number, address_street, areap, cod_dist, cod_sub_prefecture, district, id, latitude, longitude, name, reference, region_5, region_8, registration_code, setcens, sub_prefecture
2021-03-15T10:19:17 HOSTNAME APP_NAME: "DELETE /markets/4003-7 HTTP/1.1" 500 160560
2021-03-15T10:19:54 HOSTNAME APP_NAME: Watching for file changes with StatReloader
2021-03-15T10:19:56 HOSTNAME APP_NAME: "DELETE /markets/4003-7 HTTP/1.1" 204 0
2021-03-15T10:20:49 HOSTNAME APP_NAME: "POST /markets/ HTTP/1.1" 201 404
2021-03-15T10:21:15 HOSTNAME APP_NAME: Bad Request: /markets/
2021-03-15T10:21:15 HOSTNAME APP_NAME: "POST /markets/ HTTP/1.1" 400 76
2021-03-15T10:21:37 HOSTNAME APP_NAME: Bad Request: /markets/
2021-03-15T10:21:37 HOSTNAME APP_NAME: "POST /markets/ HTTP/1.1" 400 76
2021-03-15T10:22:22 HOSTNAME APP_NAME: "POST /markets/ HTTP/1.1" 201 404
2021-03-15T10:22:33 HOSTNAME APP_NAME: Internal Server Error: /markets/9998-1
Traceback (most recent call last):
  File "/home/hernangonzales/projects/test/unico/env/lib/python3.8/site-packages/django/core/handlers/exception.py", line 47, in inner
    response = get_response(request)
  File "/home/hernangonzales/projects/test/unico/env/lib/python3.8/site-packages/django/core/handlers/base.py", line 181, in _get_response
    response = wrapped_callback(request, *callback_args, **callback_kwargs)
  File "/home/hernangonzales/projects/test/unico/env/lib/python3.8/site-packages/django/views/decorators/csrf.py", line 54, in wrapped_view
    return view_func(*args, **kwargs)
  File "/home/hernangonzales/projects/test/unico/env/lib/python3.8/site-packages/django/views/generic/base.py", line 70, in view
    return self.dispatch(request, *args, **kwargs)
  File "/home/hernangonzales/projects/test/unico/env/lib/python3.8/site-packages/rest_framework/views.py", line 509, in dispatch
    response = self.handle_exception(exc)
  File "/home/hernangonzales/projects/test/unico/env/lib/python3.8/site-packages/rest_framework/views.py", line 469, in handle_exception
    self.raise_uncaught_exception(exc)
  File "/home/hernangonzales/projects/test/unico/env/lib/python3.8/site-packages/rest_framework/views.py", line 480, in raise_uncaught_exception
    raise exc
  File "/home/hernangonzales/projects/test/unico/env/lib/python3.8/site-packages/rest_framework/views.py", line 506, in dispatch
    response = handler(request, *args, **kwargs)
  File "/home/hernangonzales/projects/test/unico/env/lib/python3.8/site-packages/rest_framework/generics.py", line 285, in put
    return self.update(request, *args, **kwargs)
  File "/home/hernangonzales/projects/test/unico/env/lib/python3.8/site-packages/rest_framework/mixins.py", line 67, in update
    serializer.is_valid(raise_exception=True)
  File "/home/hernangonzales/projects/test/unico/env/lib/python3.8/site-packages/rest_framework/serializers.py", line 220, in is_valid
    self._validated_data = self.run_validation(self.initial_data)
  File "/home/hernangonzales/projects/test/unico/env/lib/python3.8/site-packages/rest_framework/serializers.py", line 419, in run_validation
    value = self.to_internal_value(data)
  File "/home/hernangonzales/projects/test/unico/env/lib/python3.8/site-packages/rest_framework/serializers.py", line 472, in to_internal_value
    for field in fields:
  File "/home/hernangonzales/projects/test/unico/env/lib/python3.8/site-packages/rest_framework/serializers.py", line 355, in _writable_fields
    for field in self.fields.values():
  File "/home/hernangonzales/projects/test/unico/env/lib/python3.8/site-packages/django/utils/functional.py", line 48, in __get__
    res = instance.__dict__[self.name] = self.func(instance)
  File "/home/hernangonzales/projects/test/unico/env/lib/python3.8/site-packages/rest_framework/serializers.py", line 349, in fields
    for key, value in self.get_fields().items():
  File "/home/hernangonzales/projects/test/unico/env/lib/python3.8/site-packages/rest_framework/serializers.py", line 1029, in get_fields
    field_names = self.get_field_names(declared_fields, info)
  File "/home/hernangonzales/projects/test/unico/env/lib/python3.8/site-packages/rest_framework/serializers.py", line 1152, in get_field_names
    assert field_name in fields, (
AssertionError: The field 'registry' was included on serializer MarketUpdatedSerializer in the 'exclude' option, but does not match any model field.
2021-03-15T10:22:33 HOSTNAME APP_NAME: "PUT /markets/9998-1 HTTP/1.1" 500 141370
2021-03-15T10:23:08 HOSTNAME APP_NAME: Internal Server Error: /markets/9998-1
Traceback (most recent call last):
  File "/home/hernangonzales/projects/test/unico/env/lib/python3.8/site-packages/django/core/handlers/exception.py", line 47, in inner
    response = get_response(request)
  File "/home/hernangonzales/projects/test/unico/env/lib/python3.8/site-packages/django/core/handlers/base.py", line 181, in _get_response
    response = wrapped_callback(request, *callback_args, **callback_kwargs)
  File "/home/hernangonzales/projects/test/unico/env/lib/python3.8/site-packages/django/views/decorators/csrf.py", line 54, in wrapped_view
    return view_func(*args, **kwargs)
  File "/home/hernangonzales/projects/test/unico/env/lib/python3.8/site-packages/django/views/generic/base.py", line 70, in view
    return self.dispatch(request, *args, **kwargs)
  File "/home/hernangonzales/projects/test/unico/env/lib/python3.8/site-packages/rest_framework/views.py", line 509, in dispatch
    response = self.handle_exception(exc)
  File "/home/hernangonzales/projects/test/unico/env/lib/python3.8/site-packages/rest_framework/views.py", line 469, in handle_exception
    self.raise_uncaught_exception(exc)
  File "/home/hernangonzales/projects/test/unico/env/lib/python3.8/site-packages/rest_framework/views.py", line 480, in raise_uncaught_exception
    raise exc
  File "/home/hernangonzales/projects/test/unico/env/lib/python3.8/site-packages/rest_framework/views.py", line 506, in dispatch
    response = handler(request, *args, **kwargs)
  File "/home/hernangonzales/projects/test/unico/env/lib/python3.8/site-packages/rest_framework/generics.py", line 285, in put
    return self.update(request, *args, **kwargs)
  File "/home/hernangonzales/projects/test/unico/env/lib/python3.8/site-packages/rest_framework/mixins.py", line 67, in update
    serializer.is_valid(raise_exception=True)
  File "/home/hernangonzales/projects/test/unico/env/lib/python3.8/site-packages/rest_framework/serializers.py", line 220, in is_valid
    self._validated_data = self.run_validation(self.initial_data)
  File "/home/hernangonzales/projects/test/unico/env/lib/python3.8/site-packages/rest_framework/serializers.py", line 419, in run_validation
    value = self.to_internal_value(data)
  File "/home/hernangonzales/projects/test/unico/env/lib/python3.8/site-packages/rest_framework/serializers.py", line 472, in to_internal_value
    for field in fields:
  File "/home/hernangonzales/projects/test/unico/env/lib/python3.8/site-packages/rest_framework/serializers.py", line 355, in _writable_fields
    for field in self.fields.values():
  File "/home/hernangonzales/projects/test/unico/env/lib/python3.8/site-packages/django/utils/functional.py", line 48, in __get__
    res = instance.__dict__[self.name] = self.func(instance)
  File "/home/hernangonzales/projects/test/unico/env/lib/python3.8/site-packages/rest_framework/serializers.py", line 349, in fields
    for key, value in self.get_fields().items():
  File "/home/hernangonzales/projects/test/unico/env/lib/python3.8/site-packages/rest_framework/serializers.py", line 1029, in get_fields
    field_names = self.get_field_names(declared_fields, info)
  File "/home/hernangonzales/projects/test/unico/env/lib/python3.8/site-packages/rest_framework/serializers.py", line 1152, in get_field_names
    assert field_name in fields, (
AssertionError: The field 'registry' was included on serializer MarketUpdatedSerializer in the 'exclude' option, but does not match any model field.
2021-03-15T10:23:08 HOSTNAME APP_NAME: "PUT /markets/9998-1 HTTP/1.1" 500 141222
2021-03-15T10:23:45 HOSTNAME APP_NAME: /home/hernangonzales/projects/test/unico/markets/serializers.py changed, reloading.
2021-03-15T10:23:46 HOSTNAME APP_NAME: Watching for file changes with StatReloader
2021-03-15T10:23:51 HOSTNAME APP_NAME: /home/hernangonzales/projects/test/unico/markets/serializers.py changed, reloading.
2021-03-15T10:23:52 HOSTNAME APP_NAME: Watching for file changes with StatReloader
2021-03-15T10:23:54 HOSTNAME APP_NAME: "PUT /markets/9998-1 HTTP/1.1" 200 375
2021-03-15T10:24:16 HOSTNAME APP_NAME: "PUT /markets/9998-1 HTTP/1.1" 200 375
2021-03-15T10:24:30 HOSTNAME APP_NAME: "DELETE /markets/9998-1 HTTP/1.1" 204 0
2021-03-15T10:24:49 HOSTNAME APP_NAME: "GET /markets?district=BRAS HTTP/1.1" 301 0
2021-03-15T10:24:49 HOSTNAME APP_NAME: "GET /markets/?district=BRAS HTTP/1.1" 200 2052
2021-03-15T10:25:08 HOSTNAME APP_NAME: "POST /markets/ HTTP/1.1" 201 404
2021-03-15T10:25:13 HOSTNAME APP_NAME: "GET /markets?district=BRAS HTTP/1.1" 301 0
2021-03-15T10:25:13 HOSTNAME APP_NAME: "GET /markets/?district=BRAS HTTP/1.1" 200 2457
2021-03-15T10:29:09 HOSTNAME APP_NAME: Watching for file changes with StatReloader
2021-03-15T10:29:14 HOSTNAME APP_NAME: Bad Request: /markets/
2021-03-15T10:29:14 HOSTNAME APP_NAME: "POST /markets/ HTTP/1.1" 400 76
2021-03-15T10:29:21 HOSTNAME APP_NAME: "DELETE /markets/9998-1 HTTP/1.1" 204 0
2021-03-15T10:29:24 HOSTNAME APP_NAME: "POST /markets/ HTTP/1.1" 201 404
2021-03-15T10:29:30 HOSTNAME APP_NAME: Bad Request: /markets/
2021-03-15T10:29:30 HOSTNAME APP_NAME: "POST /markets/ HTTP/1.1" 400 76
2021-03-15T10:29:33 HOSTNAME APP_NAME: "PUT /markets/9998-1 HTTP/1.1" 200 375
2021-03-15T10:29:36 HOSTNAME APP_NAME: "GET /markets?district=BRAS HTTP/1.1" 301 0
2021-03-15T10:29:36 HOSTNAME APP_NAME: "GET /markets/?district=BRAS HTTP/1.1" 200 2457
